Workbook

Sheet Tabella
A1: # | B1: ID | C1: Area / Fase | D1: Descrizione rischio | E1: P | F1: I | G1: P×I | H1: Livello inerente | I1: Controlli | J1: Pr | K1: Ir | L1: Pr×Ir | M1: Livello residuo | N1: OPZIONE DI TRATTAMENTO | O1: KRI | P1: Piano di trattamento | Q1: Owner | R1: Frequenza revisione | S1: Stato
A2: 1 | B2: DEV-CHANGE-INTEGRITY_ISO | C2: Progettazione e sviluppo | D2: Rischio di modifica non controllata di codice per errore involontario, intenzionale o mancata verifica di provenienza e integrità, con possibile introduzione di difetti, backdoor, incoerenze tra versioni o compromissione dell'integrità del sistema rilasciato. | E2: 3 | F2: 4 | G2: =E2*F2 -> 12 | H2: =IFERROR(IF(G2>=16,"Critico",IF(G2>=10,"Alto",IF(G2>=5,"Medio","Basso"))),"") -> Alto | I2: Codice, modelli, dataset e configurazioni sono gestiti con versionamento e il rilascio segue una procedura che prevede test, backup e possibilità di rollback. Ogni modello rilasciato è identificato tramite hash per verificarne l'integrità e viene provato in ambiente di collaudo prima della distribuzione. | J2: =IFERROR(INDEX('Rischio residuo'!$I$2:$I$32,MATCH($A2,'Rischio residuo'!$A$2:$A$32,0)),"") -> 1 | K2: =IFERROR(INDEX('Rischio residuo'!$J$2:$J$32,MATCH($A2,'Rischio residuo'!$A$2:$A$32,0)),"") -> 4 | L2: =J2*K2 -> 4 | M2: =IFERROR(IF(L2>=16,"Critico",IF(L2>=10,"Alto",IF(L2>=5,"Medio","Basso"))),"") -> Basso | N2: =IF($M2="","",IF($M2="Basso","Accettazione",IF(IFERROR(INDEX('Rischio residuo'!$F$2:$F$32,MATCH($A2,'Rischio residuo'!$A$2:$A$32,0)),0)=0,"Trasferimento","Mitigazione"))) -> Accettazione | Q2: AI Engineer | R2: Ogni rilascio | S2: =IF($N2="","",IF($N2="Accettazione","CHIUSO",IF($N2="Trasferimento","APERTO","MONITORATO"))) -> CHIUSO
A3: 2 | B3: DEV-SCALABILITY-LATENCY | C3: Progettazione e sviluppo | D3: Rischio di limiti di scalabilità, capacità computazionale o latenza incompatibili con il funzionamento atteso, con possibile degrado delle prestazioni, rallentamento dell'elaborazione o mancato rispetto dei requisiti operativi. | E3: 2 | F3: 2 | G3: =E3*F3 -> 4 | H3: =IFERROR(IF(G3>=16,"Critico",IF(G3>=10,"Alto",IF(G3>=5,"Medio","Basso"))),"") -> Basso | I3: L'architettura Edge+Core distribuisce l'elaborazione in locale, riducendo il carico sul componente centrale; dopo ogni rilascio le prestazioni e la latenza del sistema sono monitorate e verificate. | J3: =IFERROR(INDEX('Rischio residuo'!$I$2:$I$32,MATCH($A3,'Rischio residuo'!$A$2:$A$32,0)),"") -> 1 | K3: =IFERROR(INDEX('Rischio residuo'!$J$2:$J$32,MATCH($A3,'Rischio residuo'!$A$2:$A$32,0)),"") -> 2 | L3: =J3*K3 -> 2 | M3: =IFERROR(IF(L3>=16,"Critico",IF(L3>=10,"Alto",IF(L3>=5,"Medio","Basso"))),"") -> Basso | N3: =IF($M3="","",IF($M3="Basso","Accettazione",IF(IFERROR(INDEX('Rischio residuo'!$F$2:$F$32,MATCH($A3,'Rischio residuo'!$A$2:$A$32,0)),0)=0,"Trasferimento","Mitigazione"))) -> Accettazione | Q3: Responsabile informatico | R3: Trimestrale | S3: =IF($N3="","",IF($N3="Accettazione","CHIUSO",IF($N3="Trasferimento","APERTO","MONITORATO"))) -> CHIUSO
A4: 3 | B4: DATA-DATASET-POISONING | C4: Dati, addestramento e validazione | D4: Rischio di inserimento intenzionale di dati manipolati, data poisoning o backdoor nel dataset, con possibile alterazione del comportamento del modello o riduzione della sua accuratezza e affidabilità. | E4: 2 | F4: 4 | G4: =E4*F4 -> 8 | H4: =IFERROR(IF(G4>=16,"Critico",IF(G4>=10,"Alto",IF(G4>=5,"Medio","Basso"))),"") -> Medio | I4: Il retraining non è automatico: ogni aggiornamento del modello è subordinato a una verifica umana. Le immagini utilizzate sono selezionate, annotate e tracciate, con metadati che ne documentano origine ed esiti. | J4: =IFERROR(INDEX('Rischio residuo'!$I$2:$I$32,MATCH($A4,'Rischio residuo'!$A$2:$A$32,0)),"") -> 1 | K4: =IFERROR(INDEX('Rischio residuo'!$J$2:$J$32,MATCH($A4,'Rischio residuo'!$A$2:$A$32,0)),"") -> 4 | L4: =J4*K4 -> 4 | M4: =IFERROR(IF(L4>=16,"Critico",IF(L4>=10,"Alto",IF(L4>=5,"Medio","Basso"))),"") -> Basso | N4: =IF($M4="","",IF($M4="Basso","Accettazione",IF(IFERROR(INDEX('Rischio residuo'!$F$2:$F$32,MATCH($A4,'Rischio residuo'!$A$2:$A$32,0)),0)=0,"Trasferimento","Mitigazione"))) -> Accettazione | Q4: AI Engineer + Responsabile informatico | R4: Ogni rilascio | S4: =IF($N4="","",IF($N4="Accettazione","CHIUSO",IF($N4="Trasferimento","APERTO","MONITORATO"))) -> CHIUSO
A5: 4 | B5: DATA-QUALITY-VALIDATION | C5: Dati, addestramento e validazione | D5: Rischio di dataset di addestramento, validazione o test non adeguati, non rappresentativi, sbilanciati o contenenti errori, oppure di errori nella progettazione, nell'addestramento, nella validazione o nella selezione del modello, con possibile riduzione dell'accuratezza, della robustezza o della capacità di generalizzazione. | E5: 4 | F5: 3 | G5: =E5*F5 -> 12 | H5: =IFERROR(IF(G5>=16,"Critico",IF(G5>=10,"Alto",IF(G5>=5,"Medio","Basso"))),"") -> Alto | I5: Il dataset è costruito a partire da fonti diverse e riequilibrato con apposite tecniche; le prestazioni del modello sono validate su un dataset di test e il rilascio avviene solo al raggiungimento delle prestazioni minime attese. | J5: =IFERROR(INDEX('Rischio residuo'!$I$2:$I$32,MATCH($A5,'Rischio residuo'!$A$2:$A$32,0)),"") -> 2 | K5: =IFERROR(INDEX('Rischio residuo'!$J$2:$J$32,MATCH($A5,'Rischio residuo'!$A$2:$A$32,0)),"") -> 3 | L5: =J5*K5 -> 6 | M5: =IFERROR(IF(L5>=16,"Critico",IF(L5>=10,"Alto",IF(L5>=5,"Medio","Basso"))),"") -> Medio | N5: =IF($M5="","",IF($M5="Basso","Accettazione",IF(IFERROR(INDEX('Rischio residuo'!$F$2:$F$32,MATCH($A5,'Rischio residuo'!$A$2:$A$32,0)),0)=0,"Trasferimento","Mitigazione"))) -> Mitigazione | O5: I. Recall DPI < 0,70 oppure mAP50 DPI < 0,75 oppure mAP95 < 0,45 su dataset di validazione. II. N. modelli candidati selezionati per il rilascio senza evidenza di validazione o senza rispetto delle soglie minime di accettazione > 0. | P5: I. Analizzare la composizione del dataset, integrare immagini mancanti o classi sottorappresentate, riequilibrare il dataset ed eseguire nuova validazione. II. Ripetere addestramento e validazione; confrontare i modelli candidati con le soglie minime e autorizzare il rilascio solo con evidenze documentate. | Q5: AI Engineer | R5: A ogni retraining | S5: =IF($N5="","",IF($N5="Accettazione","CHIUSO",IF($N5="Trasferimento","APERTO","MONITORATO"))) -> MONITORATO
A6: 5 | B6: IMP-SYSTEM-INTEGRATION-CONFIGURATION | C6: Implementazione tecnica e integrazione | D6: Rischio di errori durante l'installazione, configurazione, integrazione, manutenzione o aggiornamento di telecamere, dispositivi Edge, componente Core, soglie, filtri spaziali, interfacce e servizi di notifica, con possibile perdita o alterazione dei flussi, mancata elaborazione degli eventi, indisponibilità o funzionamento non conforme di ISaAC. | E6: 3 | F6: 3 | G6: =E6*F6 -> 9 | H6: =IFERROR(IF(G6>=16,"Critico",IF(G6>=10,"Alto",IF(G6>=5,"Medio","Basso"))),"") -> Medio | I6: Installazione e configurazione del sistema avvengono in modo controllato e il funzionamento è verificato con un collaudo funzionale prima della messa in esercizio; gli eventi di sistema sono registrati per consentire la ricostruzione di eventuali errori. | J6: =IFERROR(INDEX('Rischio residuo'!$I$2:$I$32,MATCH($A6,'Rischio residuo'!$A$2:$A$32,0)),"") -> 2 | K6: =IFERROR(INDEX('Rischio residuo'!$J$2:$J$32,MATCH($A6,'Rischio residuo'!$A$2:$A$32,0)),"") -> 3 | L6: =J6*K6 -> 6 | M6: =IFERROR(IF(L6>=16,"Critico",IF(L6>=10,"Alto",IF(L6>=5,"Medio","Basso"))),"") -> Medio | N6: =IF($M6="","",IF($M6="Basso","Accettazione",IF(IFERROR(INDEX('Rischio residuo'!$F$2:$F$32,MATCH($A6,'Rischio residuo'!$A$2:$A$32,0)),0)=0,"Trasferimento","Mitigazione"))) -> Mitigazione | O6: I. N. errori di configurazione, installazione o integrazione rilevati durante collaudo, aggiornamento o manutenzione > 0. | P6: I. Correggere configurazioni errate, ripetere il collaudo funzionale, aggiornare la documentazione tecnica e registrare l'esito della verifica. | Q6: AI Engineer | R6: Ogni 6 mesi | S6: =IF($N6="","",IF($N6="Accettazione","CHIUSO",IF($N6="Trasferimento","APERTO","MONITORATO"))) -> MONITORATO
A7: 6 | B7: DATA-LOSS | C7: Esercizio e manutenzione | D7: Rischio di cancellazione, corruzione o perdita non intenzionale di immagini, eventi, log, dataset, configurazioni o modelli e di mancato recupero tramite le procedure di backup e ripristino, con possibile perdita permanente delle informazioni, impossibilità di ricostruire le attività, degrado del servizio o prolungamento dell'indisponibilità di ISaAC. | E7: 2 | F7: 4 | G7: =E7*F7 -> 8 | H7: =IFERROR(IF(G7>=16,"Critico",IF(G7>=10,"Alto",IF(G7>=5,"Medio","Basso"))),"") -> Medio | I7: Sono eseguiti backup periodici e prima di ogni rilascio; dati e log sono archiviati in forma cifrata e sono definite procedure di ripristino da attivare in caso di necessità. | J7: =IFERROR(INDEX('Rischio residuo'!$I$2:$I$32,MATCH($A7,'Rischio residuo'!$A$2:$A$32,0)),"") -> 2 | K7: =IFERROR(INDEX('Rischio residuo'!$J$2:$J$32,MATCH($A7,'Rischio residuo'!$A$2:$A$32,0)),"") -> 2 | L7: =J7*K7 -> 4 | M7: =IFERROR(IF(L7>=16,"Critico",IF(L7>=10,"Alto",IF(L7>=5,"Medio","Basso"))),"") -> Basso | N7: =IF($M7="","",IF($M7="Basso","Accettazione",IF(IFERROR(INDEX('Rischio residuo'!$F$2:$F$32,MATCH($A7,'Rischio residuo'!$A$2:$A$32,0)),0)=0,"Trasferimento","Mitigazione"))) -> Accettazione | Q7: AI Engineer | R7: A ogni retraining | S7: =IF($N7="","",IF($N7="Accettazione","CHIUSO",IF($N7="Trasferimento","APERTO","MONITORATO"))) -> CHIUSO
A8: 7 | B8: OPS-PIPELINE-CAPACITY-FAILURE | C8: Esercizio e manutenzione | D8: Rischio di guasto, bug o malfunzionamento della pipeline applicativa, del sistema operativo, del firmware, delle librerie, del componente Core o del servizio di notifica, oppure di capacità elaborativa insufficiente, saturazione delle risorse o latenza eccessiva, con possibile mancata acquisizione o elaborazione dei flussi, perdita di eventi o ritardo nell'intervento umano. | E8: 3 | F8: 3 | G8: =E8*F8 -> 9 | H8: =IFERROR(IF(G8>=16,"Critico",IF(G8>=10,"Alto",IF(G8>=5,"Medio","Basso"))),"") -> Medio | I8: Gli errori applicativi sono registrati e il corretto funzionamento è verificato dopo ogni aggiornamento; prestazioni e tempi di elaborazione sono monitorati e le risorse possono essere adeguate in funzione del carico. | J8: =IFERROR(INDEX('Rischio residuo'!$I$2:$I$32,MATCH($A8,'Rischio residuo'!$A$2:$A$32,0)),"") -> 2 | K8: =IFERROR(INDEX('Rischio residuo'!$J$2:$J$32,MATCH($A8,'Rischio residuo'!$A$2:$A$32,0)),"") -> 3 | L8: =J8*K8 -> 6 | M8: =IFERROR(IF(L8>=16,"Critico",IF(L8>=10,"Alto",IF(L8>=5,"Medio","Basso"))),"") -> Medio | N8: =IF($M8="","",IF($M8="Basso","Accettazione",IF(IFERROR(INDEX('Rischio residuo'!$F$2:$F$32,MATCH($A8,'Rischio residuo'!$A$2:$A$32,0)),0)=0,"Trasferimento","Mitigazione"))) -> Mitigazione | O8: I. Worker, Core, servizio di notifica o componente pipeline in stato di errore per più di 5 minuti consecutivi. II. Tempo medio di elaborazione o consegna alert > 2× valore normale per più di 10 minuti consecutivi. | P8: I. Attivare alert tecnici sui componenti critici, analizzare i log, ripristinare il servizio e documentare causa e azione correttiva. II. Analizzare carico, risorse e log applicativi; ottimizzare configurazioni o potenziare risorse Edge/Core in caso di saturazione. | Q8: Responsabile informatico | R8: Ogni rilascio/manutenzione | S8: =IF($N8="","",IF($N8="Accettazione","CHIUSO",IF($N8="Trasferimento","APERTO","MONITORATO"))) -> MONITORATO
A9: 8 | B9: INF-OUT-OF-DISTRIBUTION_ISO | C9: Inferenza e monitoraggio | D9: Rischio di comparsa di oggetti, DPI o condizioni visive fuori distribuzione, con possibile generazione di errori di rilevamento o riduzione non prevista delle prestazioni. | E9: 3 | F9: 4 | G9: =E9*F9 -> 12 | H9: =IFERROR(IF(G9>=16,"Critico",IF(G9>=10,"Alto",IF(G9>=5,"Medio","Basso"))),"") -> Alto | I9: Il sistema opera con il modello di rilevamento in esercizio, con soglia minima di confidenza ≥0,40. Il dataset è composto da immagini raccolte in contesti differenti ed è attiva la raccolta di casi operativi da impiegare per il miglioramento del modello. | J9: =IFERROR(INDEX('Rischio residuo'!$I$2:$I$32,MATCH($A9,'Rischio residuo'!$A$2:$A$32,0)),"") -> 2 | K9: =IFERROR(INDEX('Rischio residuo'!$J$2:$J$32,MATCH($A9,'Rischio residuo'!$A$2:$A$32,0)),"") -> 4 | L9: =J9*K9 -> 8 | M9: =IFERROR(IF(L9>=16,"Critico",IF(L9>=10,"Alto",IF(L9>=5,"Medio","Basso"))),"") -> Medio | N9: =IF($M9="","",IF($M9="Basso","Accettazione",IF(IFERROR(INDEX('Rischio residuo'!$F$2:$F$32,MATCH($A9,'Rischio residuo'!$A$2:$A$32,0)),0)=0,"Trasferimento","Mitigazione"))) -> Mitigazione | O9: I. mAP50 DPI < 0,75 oppure Recall DPI < 0,70, misurati sul modello in esercizio su immagini relative a nuovi DPI, nuovi ambienti o nuove condizioni operative, oppure scostamento di mAP50 o Recall superiore al 10% rispetto alla versione del modello precedentemente approvata e registrata. II. N. rilevamenti con confidenza compresa tra 0,40 e 0,70 riferiti a condizioni non rappresentate nel dataset di addestramento > 0 nel campione mensile verificato. | P9: I. Raccogliere immagini delle nuove condizioni operative, inserirle nel dataset ed eseguire fine-tuning e nuova validazione; confrontare le prestazioni con la baseline della versione del modello approvata (vedi Fascicolo Tecnico, Cap. 4) e avviare retraining o revisione della soglia di confidenza quando lo scostamento supera la tolleranza. II. Ritarare le soglie dei KRI a ogni cambio di modello, di formato di inferenza o di soglia di confidenza, documentando la nuova baseline nel Fascicolo Tecnico. | Q9: Responsabile informatico | R9: Trimestrale | S9: =IF($N9="","",IF($N9="Accettazione","CHIUSO",IF($N9="Trasferimento","APERTO","MONITORATO"))) -> MONITORATO
A10: 9 | B10: INF-FALSE-NEGATIVE_ISO | C10: Inferenza e monitoraggio | D10: Rischio che ISaAC non rilevi una reale situazione di mancato o non corretto utilizzo dei DPI (falso negativo), a causa di occlusioni/scarsa visibilità, adversarial patch, model drift o cambiamento del contesto operativo non gestito, con conseguente mancata segnalazione, ritardo nell'intervento e possibile esposizione del lavoratore a una condizione di pericolo. | E10: 4 | F10: 4 | G10: =E10*F10 -> 16 | H10: =IFERROR(IF(G10>=16,"Critico",IF(G10>=10,"Alto",IF(G10>=5,"Medio","Basso"))),"") -> Critico | I10: Il rilevamento si basa sul modello di rilevamento in esercizio, con soglia minima di confidenza ≥0,40 (abbassata da ≥0,70 con il cambio di modello) e sull'analisi di sequenze di immagini, con verifica DPI-keypoints a soglia geometrica adattiva; un filtro di inerzia genera l'allarme solo dopo cinque frame consecutivi di non conformità ed è comunque verificato da una persona, con controllo fisico dei DPI, prima di qualsiasi intervento. Le variazioni del contesto operativo sono monitorate. | J10: =IFERROR(INDEX('Rischio residuo'!$I$2:$I$32,MATCH($A10,'Rischio residuo'!$A$2:$A$32,0)),"") -> 2 | K10: =IFERROR(INDEX('Rischio residuo'!$J$2:$J$32,MATCH($A10,'Rischio residuo'!$A$2:$A$32,0)),"") -> 4 | L10: =J10*K10 -> 8 | M10: =IFERROR(IF(L10>=16,"Critico",IF(L10>=10,"Alto",IF(L10>=5,"Medio","Basso"))),"") -> Medio | N10: =IF($M10="","",IF($M10="Basso","Accettazione",IF(IFERROR(INDEX('Rischio residuo'!$F$2:$F$32,MATCH($A10,'Rischio residuo'!$A$2:$A$32,0)),0)=0,"Trasferimento","Mitigazione"))) -> Mitigazione | O10: I. N. operatori senza DPI non segnalati > 0, oppure Recall DPI < 0,70 / Precision DPI < 0,75 sul modello in esercizio (soglia di confidenza ≥0,40), oppure scostamento superiore al 10% rispetto al dataset di controllo della versione approvata. II. Percentuale di immagini non valutabili per occlusione/DPI non visibili > 10% del campione mensile verificato. III. N. casi confermati di adesivi, pattern, camuffamenti o artefatti fisici associati a errore di rilevamento > 0. IV. N. modifiche a DPI, area, telecamera, condizioni operative, soglia di confidenza (≥0,40) o numero di frame consecutivi richiesti, introdotte senza nuova verifica o validazione documentata del modello > 0. V. N. episodi reali di non conformità esauriti prima dei 5 frame consecutivi richiesti dal filtro di inerzia, e quindi non segnalati, > 0. | P10: I. Analizzare i falsi negativi, aggiungere le immagini al dataset e avviare retraining; confrontare periodicamente le prestazioni con la baseline della versione approvata e avviare retraining quando precision o recall scendono sotto soglia o si scostano oltre la tolleranza. II. Introdurre o mantenere un controllo mensile su immagini/eventi; se la soglia viene superata, correggere inquadratura, ostacoli o condizioni operative. III. Controllare i DPI sospetti, rimuovere o sostituire DPI alterati e valutare l'inserimento di casi simili nei test o nel dataset di miglioramento. IV. Rivalutare il sistema dopo modifiche operative rilevanti, raccogliendo nuove immagini e aggiornando dataset/modello; sottoporre ogni modifica di soglia di confidenza o di lunghezza del filtro di inerzia al processo di rilascio controllato, con nuova validazione e aggiornamento del Fascicolo Tecnico e del presente registro. V. Verificare la durata tipica degli episodi di non conformità nel contesto reale e valutare la riduzione del numero di frame consecutivi richiesti, bilanciandola con l'effetto sui falsi positivi | Q10: Responsabile informatico | R10: Monitoraggio continuo | S10: =IF($N10="","",IF($N10="Accettazione","CHIUSO",IF($N10="Trasferimento","APERTO","MONITORATO"))) -> MONITORATO
A11: 10 | B11: INF-FALSE-POSITIVE_ISO | C11: Inferenza e monitoraggio | D11: Rischio di generazione di una segnalazione di non conformità non corretta (falso positivo) a causa di occlusioni/scarsa visibilità, adversarial patch, model drift o cambiamento del contesto operativo non gestito, con possibile sovraccarico operativo, perdita di fiducia nel sistema o interventi non necessari. | E11: 4 | F11: 4 | G11: =E11*F11 -> 16 | H11: =IFERROR(IF(G11>=16,"Critico",IF(G11>=10,"Alto",IF(G11>=5,"Medio","Basso"))),"") -> Critico | I11: Il sistema opera con soglia minima di confidenza ≥0,40: la soglia più permissiva è compensata da un filtro di inerzia che genera l'allarme solo dopo cinque frame consecutivi di non conformità. Ogni allarme è verificato da una persona sullo snapshot prima di qualsiasi intervento; è disponibile un canale per segnalare errori e le variazioni del contesto operativo sono monitorate. | J11: =IFERROR(INDEX('Rischio residuo'!$I$2:$I$32,MATCH($A11,'Rischio residuo'!$A$2:$A$32,0)),"") -> 3 | K11: =IFERROR(INDEX('Rischio residuo'!$J$2:$J$32,MATCH($A11,'Rischio residuo'!$A$2:$A$32,0)),"") -> 4 | L11: =J11*K11 -> 12 | M11: =IFERROR(IF(L11>=16,"Critico",IF(L11>=10,"Alto",IF(L11>=5,"Medio","Basso"))),"") -> Alto | N11: =IF($M11="","",IF($M11="Basso","Accettazione",IF(IFERROR(INDEX('Rischio residuo'!$F$2:$F$32,MATCH($A11,'Rischio residuo'!$A$2:$A$32,0)),0)=0,"Trasferimento","Mitigazione"))) -> Mitigazione | O11: I. Percentuale di allarmi verificati non conformi al reale (falsi positivi) > 20% degli allarmi del campione mensile, oppure Precision DPI < 0,75 sul modello in esercizio (soglia di confidenza ≥0,40), oppure scostamento superiore al 10% rispetto al dataset di controllo della versione approvata. II. N. falsi positivi ricorrenti concentrati sulla stessa classe di DPI, area o telecamera > 0 nel campione mensile verificato. III. N. segnalazioni di errore ricevute dagli operatori e non analizzate entro i tempi definiti > 0. IV. N. modifiche a soglia di confidenza (≥0,40), numero di frame consecutivi richiesti, DPI, area, telecamera o condizioni operative, introdotte senza nuova verifica o validazione documentata del modello > 0. V. N. episodi di disattivazione, elusione o mancata gestione degli allarmi da parte degli operatori a causa di un eccesso di falsi positivi > 0. | P11: I. Analizzare i falsi positivi ricorrenti per classe, area e telecamera, integrare i casi nel dataset e avviare retraining. II. Valutare l'innalzamento della soglia di confidenza o l'estensione del filtro di inerzia, verificando l'effetto sui falsi negativi (Rischio 9) prima di applicare la modifica. III. Definire tempi e responsabilità per l'analisi delle segnalazioni ricevute e tracciare le azioni correttive fino alla chiusura. IV. Sottoporre ogni modifica dei parametri di inferenza al processo di rilascio controllato, con validazione documentata e aggiornamento del Fascicolo Tecnico e del presente registro. | Q11: Responsabile informatico | R11: Dopo ogni aggiornamento | S11: =IF($N11="","",IF($N11="Accettazione","CHIUSO",IF($N11="Trasferimento","APERTO","MONITORATO"))) -> MONITORATO
A12: 11 | B12: USE-AI-LITERACY-SUPERVISION_ISO | C12: Utilizzo e supervisione umana | D12: Rischio che gli utilizzatori o i supervisori di ISaAC non dispongano di competenze e AI literacy adeguate per utilizzare correttamente il sistema, comprenderne i limiti e interpretarne i risultati, con possibile mancata individuazione di errori o anomalie e adozione di decisioni non appropriate. | E12: 3 | F12: 4 | G12: =E12*F12 -> 12 | H12: =IFERROR(IF(G12>=16,"Critico",IF(G12>=10,"Alto",IF(G12>=5,"Medio","Basso"))),"") -> Alto | I12: Gli operatori dispongono di documentazione e materiale informativo e ricevono una formazione iniziale sulla corretta interpretazione degli allarmi, con indicazioni operative di riferimento e un canale a cui rivolgersi in caso di dubbi. | J12: =IFERROR(INDEX('Rischio residuo'!$I$2:$I$32,MATCH($A12,'Rischio residuo'!$A$2:$A$32,0)),"") -> 2 | K12: =IFERROR(INDEX('Rischio residuo'!$J$2:$J$32,MATCH($A12,'Rischio residuo'!$A$2:$A$32,0)),"") -> 4 | L12: =J12*K12 -> 8 | M12: =IFERROR(IF(L12>=16,"Critico",IF(L12>=10,"Alto",IF(L12>=5,"Medio","Basso"))),"") -> Medio | N12: Trasferimento | O12: I. N. utenti, responsabili o tecnici coinvolti nell'uso/supervisione del sistema privi di istruzioni o documentazione aggiornata > 0. II. Assenza di una clausola contrattuale che attribuisca al cliente l'obbligo di formazione e AI literacy degli utilizzatori (art. 4 Reg. UE 2024/1689), oppure assenza di evidenza della formazione erogata agli utenti finali. | Q12: Cliente | R12: Annuale (rinnovo contratto) e a ogni nuovo gruppo di utilizzatori | S12: =IF($N12="","",IF($N12="Accettazione","CHIUSO",IF($N12="Trasferimento","APERTO","MONITORATO"))) -> APERTO
A13: 12 | B13: USE-OVERSIGHT-VERIFICATION-FAILURE_ISO | C13: Utilizzo e supervisione umana | D13: Rischio che le segnalazioni prodotte da ISaAC non siano verificate, comunicate o gestite tempestivamente e correttamente, per fiducia eccessiva o mancata considerazione delle segnalazioni (automation bias) oppure per segnalazione tardiva o assente di anomalie, errori del modello, falsi positivi o falsi negativi, con possibile conferma di risultati errati o mancata gestione di situazioni reali. | E13: 3 | F13: 4 | G13: =E13*F13 -> 12 | H13: =IFERROR(IF(G13>=16,"Critico",IF(G13>=10,"Alto",IF(G13>=5,"Medio","Basso"))),"") -> Alto | I13: Ogni allarme è verificato da un responsabile prima di qualsiasi intervento ed è disponibile un canale dedicato per la segnalazione di anomalie ed errori. | J13: =IFERROR(INDEX('Rischio residuo'!$I$2:$I$32,MATCH($A13,'Rischio residuo'!$A$2:$A$32,0)),"") -> 2 | K13: =IFERROR(INDEX('Rischio residuo'!$J$2:$J$32,MATCH($A13,'Rischio residuo'!$A$2:$A$32,0)),"") -> 4 | L13: =J13*K13 -> 8 | M13: =IFERROR(IF(L13>=16,"Critico",IF(L13>=10,"Alto",IF(L13>=5,"Medio","Basso"))),"") -> Medio | N13: =IF($M13="","",IF($M13="Basso","Accettazione",IF(IFERROR(INDEX('Rischio residuo'!$F$2:$F$32,MATCH($A13,'Rischio residuo'!$A$2:$A$32,0)),0)=0,"Trasferimento","Mitigazione"))) -> Mitigazione | O13: I. N. azioni correttive adottate senza verifica umana dello snapshot o senza valutazione dell'attendibilità dell'allarme > 0. II. N. allarmi non verificati dal responsabile prima dell'azione correttiva > 0. III. N. falsi positivi, falsi negativi o anomalie confermati non segnalati al supporto tecnico entro il periodo previsto > 0. | P13: I. Richiamare l'obbligo di verifica umana, aggiornare le istruzioni operative e riesaminare i casi in cui l'allarme sia stato seguito automaticamente. II. Formalizzare il passaggio di verifica umana, registrare l'esito della verifica e richiamare i responsabili alla procedura. III. Definire tempi e canali di segnalazione; analizzare le anomalie ricevute e tracciare le azioni correttive fino alla chiusura. | Q13: Responsabile della sicurezza | R13: Mensile | S13: =IF($N13="","",IF($N13="Accettazione","CHIUSO",IF($N13="Trasferimento","APERTO","MONITORATO"))) -> MONITORATO
A14: 13 | B14: SEC-ACCESS-CREDENTIAL-MISUSE | C14: Cybersecurity | D14: Rischio di accesso non autorizzato ai componenti e ai dati di ISaAC per errata configurazione, assegnazione o mancata revoca di account/privilegi/API key, per abuso intenzionale o condivisione impropria di credenziali da parte di soggetti autorizzati, oppure per acquisizione fraudolenta delle credenziali (brute force, phishing, credential stuffing, social engineering). | E14: 3 | F14: 4 | G14: =E14*F14 -> 12 | H14: =IFERROR(IF(G14>=16,"Critico",IF(G14>=10,"Alto",IF(G14>=5,"Medio","Basso"))),"") -> Alto | I14: L'accesso avviene con credenziali dedicate soggette ad autenticazione, autorizzazione e revoca, con segregazione dei permessi tra i diversi componenti del sistema. | J14: =IFERROR(INDEX('Rischio residuo'!$I$2:$I$32,MATCH($A14,'Rischio residuo'!$A$2:$A$32,0)),"") -> 1 | K14: =IFERROR(INDEX('Rischio residuo'!$J$2:$J$32,MATCH($A14,'Rischio residuo'!$A$2:$A$32,0)),"") -> 4 | L14: =J14*K14 -> 4 | M14: =IFERROR(IF(L14>=16,"Critico",IF(L14>=10,"Alto",IF(L14>=5,"Medio","Basso"))),"") -> Basso | N14: =IF($M14="","",IF($M14="Basso","Accettazione",IF(IFERROR(INDEX('Rischio residuo'!$F$2:$F$32,MATCH($A14,'Rischio residuo'!$A$2:$A$32,0)),0)=0,"Trasferimento","Mitigazione"))) -> Accettazione | Q14: AI Engineer + Responsabile della sicurezza | R14: Trimestrale e a ogni variazione di account, privilegi o API key | S14: =IF($N14="","",IF($N14="Accettazione","CHIUSO",IF($N14="Trasferimento","APERTO","MONITORATO"))) -> CHIUSO
A15: 14 | B15: SEC-NETWORK-COMMUNICATION-COMPROMISE | C15: Cybersecurity | D15: Rischio di compromissione delle comunicazioni o dei flussi di rete di ISaAC mediante intercettazione/sniffing passivo, attacco man-in-the-middle o dirottamento di sessione, oppure creazione, modifica, sostituzione o ritrasmissione fraudolenta di flussi video, messaggi o eventi (spoofing, replay, impersonificazione), con possibile acquisizione, alterazione o occultamento non autorizzati di dati ed eventi. | E15: 2 | F15: 4 | G15: =E15*F15 -> 8 | H15: =IFERROR(IF(G15>=16,"Critico",IF(G15>=10,"Alto",IF(G15>=5,"Medio","Basso"))),"") -> Medio | I15: Il sistema opera su un segmento di rete dedicato e le comunicazioni tra i componenti sono protette, autenticate e soggette a controllo dell'identità dei dispositivi che dialogano. | J15: =IFERROR(INDEX('Rischio residuo'!$I$2:$I$32,MATCH($A15,'Rischio residuo'!$A$2:$A$32,0)),"") -> 1 | K15: =IFERROR(INDEX('Rischio residuo'!$J$2:$J$32,MATCH($A15,'Rischio residuo'!$A$2:$A$32,0)),"") -> 4 | L15: =J15*K15 -> 4 | M15: =IFERROR(IF(L15>=16,"Critico",IF(L15>=10,"Alto",IF(L15>=5,"Medio","Basso"))),"") -> Basso | N15: =IF($M15="","",IF($M15="Basso","Accettazione",IF(IFERROR(INDEX('Rischio residuo'!$F$2:$F$32,MATCH($A15,'Rischio residuo'!$A$2:$A$32,0)),0)=0,"Trasferimento","Mitigazione"))) -> Accettazione | Q15: AI Engineer | R15: Mensile | S15: =IF($N15="","",IF($N15="Accettazione","CHIUSO",IF($N15="Trasferimento","APERTO","MONITORATO"))) -> CHIUSO
A16: 15 | B16: SEC-RECON-VULNERABILITY-EXPLOITATION | C16: Cybersecurity | D16: Rischio che vulnerabilità di software, firmware, API, servizi o altri componenti di ISaAC non siano tempestivamente individuate o corrette a causa di hardening, patching o gestione delle vulnerabilità insufficienti, anche a seguito di attività di network scanning, fingerprinting o ricognizione non autorizzata, con possibile sfruttamento per eseguire codice, acquisire privilegi o compromettere il sistema. | E16: 2 | F16: 4 | G16: =E16*F16 -> 8 | H16: =IFERROR(IF(G16>=16,"Critico",IF(G16>=10,"Alto",IF(G16>=5,"Medio","Basso"))),"") -> Medio | I16: L'accesso ai servizi è limitato alla rete interna, le versioni software sono gestite in modo controllato con test prima degli aggiornamenti e sono svolte verifiche periodiche delle vulnerabilità. | J16: =IFERROR(INDEX('Rischio residuo'!$I$2:$I$32,MATCH($A16,'Rischio residuo'!$A$2:$A$32,0)),"") -> 1 | K16: =IFERROR(INDEX('Rischio residuo'!$J$2:$J$32,MATCH($A16,'Rischio residuo'!$A$2:$A$32,0)),"") -> 4 | L16: =J16*K16 -> 4 | M16: =IFERROR(IF(L16>=16,"Critico",IF(L16>=10,"Alto",IF(L16>=5,"Medio","Basso"))),"") -> Basso | N16: =IF($M16="","",IF($M16="Basso","Accettazione",IF(IFERROR(INDEX('Rischio residuo'!$F$2:$F$32,MATCH($A16,'Rischio residuo'!$A$2:$A$32,0)),0)=0,"Trasferimento","Mitigazione"))) -> Accettazione | Q16: Responsabile informatico + Responsabile della sicurezza | R16: Ogni 6 mesi e dopo ogni caso rilevato | S16: =IF($N16="","",IF($N16="Accettazione","CHIUSO",IF($N16="Trasferimento","APERTO","MONITORATO"))) -> CHIUSO
A17: 16 | B17: SEC-INTENTIONAL-DATA-MODEL-CHANGE | C17: Cybersecurity | D17: Rischio di cancellazione o modifica di modelli, dataset, configurazioni, immagini o log, con possibile perdita di integrità, disponibilità o tracciabilità. | E17: 2 | F17: 5 | G17: =E17*F17 -> 10 | H17: =IFERROR(IF(G17>=16,"Critico",IF(G17>=10,"Alto",IF(G17>=5,"Medio","Basso"))),"") -> Alto | I17: I modelli rilasciati sono identificati tramite hash e la procedura di rilascio è controllata, con backup precedente al rilascio; le modifiche di configurazione sono registrate. | J17: =IFERROR(INDEX('Rischio residuo'!$I$2:$I$32,MATCH($A17,'Rischio residuo'!$A$2:$A$32,0)),"") -> 1 | K17: =IFERROR(INDEX('Rischio residuo'!$J$2:$J$32,MATCH($A17,'Rischio residuo'!$A$2:$A$32,0)),"") -> 5 | L17: =J17*K17 -> 5 | M17: =IFERROR(IF(L17>=16,"Critico",IF(L17>=10,"Alto",IF(L17>=5,"Medio","Basso"))),"") -> Medio | N17: =IF($M17="","",IF($M17="Basso","Accettazione",IF(IFERROR(INDEX('Rischio residuo'!$F$2:$F$32,MATCH($A17,'Rischio residuo'!$A$2:$A$32,0)),0)=0,"Trasferimento","Mitigazione"))) -> Mitigazione | O17: I. N. modifiche a modelli, dataset, configurazioni, immagini o log prive di corrispondenza nel registro dei rilasci o nel log eventi > 0. II. N. verifiche dell'hash del modello in esercizio non corrispondenti alla versione approvata e registrata > 0. III. Assenza di conservazione dei log su supporto separato e non riscrivibile dagli account che operano sul sistema. | P17: I. Verificare periodicamente l'hash del modello in esercizio contro la versione approvata e riconciliare le modifiche di configurazione con il registro dei rilasci, documentando l'esito. II. Conservare i log e le evidenze su supporto separato e non riscrivibile dagli account che operano sul sistema, in modo che una modifica intenzionale non possa cancellare anche la propria traccia. III. Verificare con evidenza documentale il ripristino di modelli, dataset e configurazioni dai backup; a contenimento dimostrato, rivalutare l'impatto residuo del rischio. | Q17: AI Engineer | R17: Ogni modifica rilevante | S17: =IF($N17="","",IF($N17="Accettazione","CHIUSO",IF($N17="Trasferimento","APERTO","MONITORATO"))) -> MONITORATO
A18: 17 | B18: SEC-MALWARE | C18: Cybersecurity | D18: Rischio di Malware, ransomware, altro codice malevolo, con possibile indisponibilità dei servizi, perdita o alterazione dei dati e accesso non autorizzato. | E18: 3 | F18: 4 | G18: =E18*F18 -> 12 | H18: =IFERROR(IF(G18>=16,"Critico",IF(G18>=10,"Alto",IF(G18>=5,"Medio","Basso"))),"") -> Alto | I18: Il sistema è installato in rete interna, i componenti sono mantenuti aggiornati, i backup sono eseguiti periodicamente e gli eventi di sicurezza sono registrati. | J18: =IFERROR(INDEX('Rischio residuo'!$I$2:$I$32,MATCH($A18,'Rischio residuo'!$A$2:$A$32,0)),"") -> 2 | K18: =IFERROR(INDEX('Rischio residuo'!$J$2:$J$32,MATCH($A18,'Rischio residuo'!$A$2:$A$32,0)),"") -> 2 | L18: =J18*K18 -> 4 | M18: =IFERROR(IF(L18>=16,"Critico",IF(L18>=10,"Alto",IF(L18>=5,"Medio","Basso"))),"") -> Basso | N18: =IF($M18="","",IF($M18="Basso","Accettazione",IF(IFERROR(INDEX('Rischio residuo'!$F$2:$F$32,MATCH($A18,'Rischio residuo'!$A$2:$A$32,0)),0)=0,"Trasferimento","Mitigazione"))) -> Accettazione | Q18: Responsabile della sicurezza | R18: Semestrale | S18: =IF($N18="","",IF($N18="Accettazione","CHIUSO",IF($N18="Trasferimento","APERTO","MONITORATO"))) -> CHIUSO
A19: 18 | B19: SEC-DENIAL-OF-SERVICE | C19: Cybersecurity | D19: Rischio di attacco alla disponibilità mediante DoS, DDoS o flooding, con possibile rallentamento o indisponibilità dei servizi di rilevamento e notifica. | E19: 2 | F19: 3 | G19: =E19*F19 -> 6 | H19: =IFERROR(IF(G19>=16,"Critico",IF(G19>=10,"Alto",IF(G19>=5,"Medio","Basso"))),"") -> Medio | I19: Il sistema è installato in rete interna e non è esposto direttamente a internet; i componenti sono monitorati per garantirne la continuità di funzionamento. | J19: =IFERROR(INDEX('Rischio residuo'!$I$2:$I$32,MATCH($A19,'Rischio residuo'!$A$2:$A$32,0)),"") -> 1 | K19: =IFERROR(INDEX('Rischio residuo'!$J$2:$J$32,MATCH($A19,'Rischio residuo'!$A$2:$A$32,0)),"") -> 3 | L19: =J19*K19 -> 3 | M19: =IFERROR(IF(L19>=16,"Critico",IF(L19>=10,"Alto",IF(L19>=5,"Medio","Basso"))),"") -> Basso | N19: =IF($M19="","",IF($M19="Basso","Accettazione",IF(IFERROR(INDEX('Rischio residuo'!$F$2:$F$32,MATCH($A19,'Rischio residuo'!$A$2:$A$32,0)),0)=0,"Trasferimento","Mitigazione"))) -> Accettazione | Q19: Responsabile della sicurezza | R19: Semestrale | S19: =IF($N19="","",IF($N19="Accettazione","CHIUSO",IF($N19="Trasferimento","APERTO","MONITORATO"))) -> CHIUSO
A20: 19 | B20: CONT-ENVIRONMENTAL-EXPOSURE | C20: Sicurezza fisica e continuità operativa | D20: Rischio di incendio, allagamento, evento sismico, fenomeno meteorologico estremo o fulminazione, oppure di esposizione prolungata a polvere, umidità, temperature fuori specifica o condizioni di illuminazione avverse, con possibile danneggiamento delle apparecchiature, degrado progressivo dei dispositivi o indisponibilità temporanea o prolungata di ISaAC. | E20: 3 | F20: 3 | G20: =E20*F20 -> 9 | H20: =IFERROR(IF(G20>=16,"Critico",IF(G20>=10,"Alto",IF(G20>=5,"Medio","Basso"))),"") -> Medio | I20: Non sono disponibili controlli diretti su questo rischio | J20: =IFERROR(INDEX('Rischio residuo'!$I$2:$I$32,MATCH($A20,'Rischio residuo'!$A$2:$A$32,0)),"") -> 3 | K20: =IFERROR(INDEX('Rischio residuo'!$J$2:$J$32,MATCH($A20,'Rischio residuo'!$A$2:$A$32,0)),"") -> 3 | L20: =J20*K20 -> 9 | M20: =IFERROR(IF(L20>=16,"Critico",IF(L20>=10,"Alto",IF(L20>=5,"Medio","Basso"))),"") -> Medio | N20: =IF($M20="","",IF($M20="Basso","Accettazione",IF(IFERROR(INDEX('Rischio residuo'!$F$2:$F$32,MATCH($A20,'Rischio residuo'!$A$2:$A$32,0)),0)=0,"Trasferimento","Mitigazione"))) -> Trasferimento | O20: I. N. eventi ambientali (incendio, allagamento, danneggiamento da eventi naturali) che colpiscono le apparecchiature senza copertura assicurativa/piano di continuità del cliente > 0. II. Assenza di un accordo contrattuale con il cliente che attribuisca formalmente la protezione ambientale dei locali e delle apparecchiature e la copertura assicurativa dei danni, oppure accordo scaduto o non documentato. | Q20: Cliente | R20: Annuale (rinnovo contratto e polizza) | S20: =IF($N20="","",IF($N20="Accettazione","CHIUSO",IF($N20="Trasferimento","APERTO","MONITORATO"))) -> APERTO
A21: 20 | B21: CONT-INFRASTRUCTURE-EQUIPMENT-FAILURE | C21: Sicurezza fisica e continuità operativa | D21: Rischio di guasto dell'alimentazione elettrica, del raffreddamento o di altre utilities, oppure di guasto, spostamento, indisponibilità o degrado di una telecamera, di un dispositivo Edge, di apparati/servizi di rete o di sistemi di memorizzazione, con possibile arresto dei componenti, perdita della copertura dell'area o indisponibilità del servizio. | E21: 3 | F21: 4 | G21: =E21*F21 -> 12 | H21: =IFERROR(IF(G21>=16,"Critico",IF(G21>=10,"Alto",IF(G21>=5,"Medio","Basso"))),"") -> Alto | I21: Non sono disponibili controlli diretti su questo rischio | J21: =IFERROR(INDEX('Rischio residuo'!$I$2:$I$32,MATCH($A21,'Rischio residuo'!$A$2:$A$32,0)),"") -> 3 | K21: =IFERROR(INDEX('Rischio residuo'!$J$2:$J$32,MATCH($A21,'Rischio residuo'!$A$2:$A$32,0)),"") -> 4 | L21: =J21*K21 -> 12 | M21: =IFERROR(IF(L21>=16,"Critico",IF(L21>=10,"Alto",IF(L21>=5,"Medio","Basso"))),"") -> Alto | N21: =IF($M21="","",IF($M21="Basso","Accettazione",IF(IFERROR(INDEX('Rischio residuo'!$F$2:$F$32,MATCH($A21,'Rischio residuo'!$A$2:$A$32,0)),0)=0,"Trasferimento","Mitigazione"))) -> Trasferimento | O21: I. N. guasti a telecamere o dispositivi Edge non rilevati tempestivamente o non ripristinati entro il tempo concordato con il cliente > 0. II. Assenza di un accordo contrattuale con il cliente che attribuisca formalmente alimentazione, continuità delle utilities e tempi di ripristino delle apparecchiature, oppure accordo scaduto o non documentato. | Q21: Fornitore hardware | R21: Annuale (rinnovo contratto di assistenza) | S21: =IF($N21="","",IF($N21="Accettazione","CHIUSO",IF($N21="Trasferimento","APERTO","MONITORATO"))) -> APERTO
A22: 21 | B22: CONT-UNAUTHORIZED-PHYSICAL-ACCESS | C22: Sicurezza fisica e continuità operativa | D22: Rischio di accesso fisico non autorizzato a telecamere, dispositivi Edge, apparati di rete, sistemi di memorizzazione o locali tecnici di ISaAC, con possibile furto, sottrazione, sabotaggio o manomissione delle apparecchiature e dei dati, alterazione dei flussi e interruzione del servizio. | E22: 2 | F22: 4 | G22: =E22*F22 -> 8 | H22: =IFERROR(IF(G22>=16,"Critico",IF(G22>=10,"Alto",IF(G22>=5,"Medio","Basso"))),"") -> Medio | I22: Non sono disponibili controlli diretti su questo rischio | J22: =IFERROR(INDEX('Rischio residuo'!$I$2:$I$32,MATCH($A22,'Rischio residuo'!$A$2:$A$32,0)),"") -> 2 | K22: =IFERROR(INDEX('Rischio residuo'!$J$2:$J$32,MATCH($A22,'Rischio residuo'!$A$2:$A$32,0)),"") -> 4 | L22: =J22*K22 -> 8 | M22: =IFERROR(IF(L22>=16,"Critico",IF(L22>=10,"Alto",IF(L22>=5,"Medio","Basso"))),"") -> Medio | N22: =IF($M22="","",IF($M22="Basso","Accettazione",IF(IFERROR(INDEX('Rischio residuo'!$F$2:$F$32,MATCH($A22,'Rischio residuo'!$A$2:$A$32,0)),0)=0,"Trasferimento","Mitigazione"))) -> Trasferimento | O22: I. N. accessi non autorizzati all'area o alle apparecchiature rilevati, oppure assenza del controllo visivo periodico nelle attività di manutenzione previste > 0. II. Assenza di un accordo contrattuale o SLA con il cliente che attribuisca formalmente il presidio fisico dei locali tecnici e delle apparecchiature, oppure accordo scaduto o non documentato. | Q22: Cliente | R22: Annuale (rinnovo contratto) e a ogni segnalazione di manomissione | S22: =IF($N22="","",IF($N22="Accettazione","CHIUSO",IF($N22="Trasferimento","APERTO","MONITORATO"))) -> APERTO
A23: 22 | B23: CONT-STAFF-UNAVAILABILITY | C23: Sicurezza fisica e continuità operativa | D23: Rischio di indisponibilità estesa del personale incaricato della supervisione, della verifica delle segnalazioni e della manutenzione di ISaAC, con possibile mancata gestione delle segnalazioni prodotte, sospensione delle attività di controllo e prolungamento dei tempi di ripristino. | E23: 2 | F23: 3 | G23: =E23*F23 -> 6 | H23: =IFERROR(IF(G23>=16,"Critico",IF(G23>=10,"Alto",IF(G23>=5,"Medio","Basso"))),"") -> Medio | I23: Non sono disponibili controlli diretti su questo rischio | J23: =IFERROR(INDEX('Rischio residuo'!$I$2:$I$32,MATCH($A23,'Rischio residuo'!$A$2:$A$32,0)),"") -> 2 | K23: =IFERROR(INDEX('Rischio residuo'!$J$2:$J$32,MATCH($A23,'Rischio residuo'!$A$2:$A$32,0)),"") -> 3 | L23: =J23*K23 -> 6 | M23: =IFERROR(IF(L23>=16,"Critico",IF(L23>=10,"Alto",IF(L23>=5,"Medio","Basso"))),"") -> Medio | N23: =IF($M23="","",IF($M23="Basso","Accettazione",IF(IFERROR(INDEX('Rischio residuo'!$F$2:$F$32,MATCH($A23,'Rischio residuo'!$A$2:$A$32,0)),0)=0,"Trasferimento","Mitigazione"))) -> Trasferimento | O23: I. N. periodi in cui nessun operatore è disponibile per la supervisione o la gestione delle segnalazioni oltre la soglia concordata > 0. II. Assenza di un accordo contrattuale con il cliente che attribuisca formalmente la disponibilità del personale di supervisione e le soglie di copertura del servizio, oppure accordo scaduto o non documentato. | Q23: Cliente | R23: Annuale (rinnovo contratto di assistenza) | S23: =IF($N23="","",IF($N23="Accettazione","CHIUSO",IF($N23="Trasferimento","APERTO","MONITORATO"))) -> APERTO
A24: 23 | B24: PRIV-UNLAWFUL-DATA-PROCESSING_GDPR | C24: Privacy e protezione dei dati | D24: Rischio di accesso, utilizzo, comunicazione o divulgazione non autorizzati di immagini, eventi, log o altri dati personali trattati mediante ISaAC, oppure di raccolta o utilizzo non autorizzato di dati personali, sensibili o protetti da diritto d'autore, con possibile violazione della riservatezza o della normativa applicabile e lesione dei diritti degli interessati. | E24: 3 | F24: 4 | G24: =E24*F24 -> 12 | H24: =IFERROR(IF(G24>=16,"Critico",IF(G24>=10,"Alto",IF(G24>=5,"Medio","Basso"))),"") -> Alto | I24: L'accesso alle immagini è limitato al personale autorizzato e le immagini inviate nelle notifiche sono anonimizzate; sono verificate le condizioni di utilizzo dei dataset ed è garantita la tracciabilità dei dati impiegati per il miglioramento del modello. | J24: =IFERROR(INDEX('Rischio residuo'!$I$2:$I$32,MATCH($A24,'Rischio residuo'!$A$2:$A$32,0)),"") -> 1 | K24: =IFERROR(INDEX('Rischio residuo'!$J$2:$J$32,MATCH($A24,'Rischio residuo'!$A$2:$A$32,0)),"") -> 4 | L24: =J24*K24 -> 4 | M24: =IFERROR(IF(L24>=16,"Critico",IF(L24>=10,"Alto",IF(L24>=5,"Medio","Basso"))),"") -> Basso | N24: =IF($M24="","",IF($M24="Basso","Accettazione",IF(IFERROR(INDEX('Rischio residuo'!$F$2:$F$32,MATCH($A24,'Rischio residuo'!$A$2:$A$32,0)),0)=0,"Trasferimento","Mitigazione"))) -> Accettazione | Q24: Responsabile informatico | R24: Trimestrale | S24: =IF($N24="","",IF($N24="Accettazione","CHIUSO",IF($N24="Trasferimento","APERTO","MONITORATO"))) -> CHIUSO
A25: 24 | B25: PRIV-RETENTION-SUBJECT-RIGHTS_GDPR | C25: Privacy e protezione dei dati | D25: Rischio di conservazione di immagini, eventi e log oltre i tempi stabiliti o di mancata cancellazione al termine del periodo previsto, oppure di mancata o non tempestiva gestione delle richieste esercitate dagli interessati, con possibile violazione del principio di limitazione della conservazione e degli obblighi applicabili. | E25: 3 | F25: 3 | G25: =E25*F25 -> 9 | H25: =IFERROR(IF(G25>=16,"Critico",IF(G25>=10,"Alto",IF(G25>=5,"Medio","Basso"))),"") -> Medio | I25: Log e immagini sono conservati per tempi definiti e archiviati su supporti cifrati; il DPO è coinvolto ed è stata svolta la valutazione d'impatto, con una gestione strutturata delle richieste degli interessati. | J25: =IFERROR(INDEX('Rischio residuo'!$I$2:$I$32,MATCH($A25,'Rischio residuo'!$A$2:$A$32,0)),"") -> 1 | K25: =IFERROR(INDEX('Rischio residuo'!$J$2:$J$32,MATCH($A25,'Rischio residuo'!$A$2:$A$32,0)),"") -> 3 | L25: =J25*K25 -> 3 | M25: =IFERROR(IF(L25>=16,"Critico",IF(L25>=10,"Alto",IF(L25>=5,"Medio","Basso"))),"") -> Basso | N25: =IF($M25="","",IF($M25="Basso","Accettazione",IF(IFERROR(INDEX('Rischio residuo'!$F$2:$F$32,MATCH($A25,'Rischio residuo'!$A$2:$A$32,0)),0)=0,"Trasferimento","Mitigazione"))) -> Accettazione | Q25: Responsabile informatico | R25: Trimestrale | S25: =IF($N25="","",IF($N25="Accettazione","CHIUSO",IF($N25="Trasferimento","APERTO","MONITORATO"))) -> CHIUSO
A26: 25 | B26: SUP-SUPPLIER-DEPENDENCY_ISO | C26: Fornitori e dipendenze esterne | D26: Rischio di dipendenza da fornitori, tecnologie o componenti critici non facilmente sostituibili, con possibile discontinuità, inadempienza o cessazione del supporto oppure modifiche unilaterali o non controllate del produttore a modelli, librerie, componenti o condizioni del servizio, con conseguente indisponibilità di aggiornamenti/assistenza o degrado/interruzione di ISaAC. | E26: 2 | F26: 3 | G26: =E26*F26 -> 6 | H26: =IFERROR(IF(G26>=16,"Critico",IF(G26>=10,"Alto",IF(G26>=5,"Medio","Basso"))),"") -> Medio | I26: I componenti software sono forniti tramite licenza commerciale regolata da un contratto definito. | J26: =IFERROR(INDEX('Rischio residuo'!$I$2:$I$32,MATCH($A26,'Rischio residuo'!$A$2:$A$32,0)),"") -> 2 | K26: =IFERROR(INDEX('Rischio residuo'!$J$2:$J$32,MATCH($A26,'Rischio residuo'!$A$2:$A$32,0)),"") -> 3 | L26: =J26*K26 -> 6 | M26: =IFERROR(IF(L26>=16,"Critico",IF(L26>=10,"Alto",IF(L26>=5,"Medio","Basso"))),"") -> Medio | N26: =IF($M26="","",IF($M26="Basso","Accettazione",IF(IFERROR(INDEX('Rischio residuo'!$F$2:$F$32,MATCH($A26,'Rischio residuo'!$A$2:$A$32,0)),0)=0,"Trasferimento","Mitigazione"))) -> Mitigazione | O26: I. N. componenti software, librerie o modelli critici per cui il supporto del produttore è cessato o dichiarato in dismissione > 0. II. N. modifiche unilaterali a licenze, versioni o condizioni di servizio introdotte dal fornitore senza il preavviso concordato > 0. III. Assenza di un contratto di fornitura o assistenza valido e non scaduto per almeno un componente critico. | P26: I. Mantenere l'inventario dei componenti critici con versione e stato di supporto; individuare in anticipo alternative sostituibili per quelli in dismissione. II. Formalizzare in contratto i termini di preavviso per modifiche a licenze, versioni e condizioni di servizio. III. Verificare a ogni revisione periodica la validità dei contratti di fornitura e assistenza sui componenti critici. | Q26: Responsabile informatico | R26: Trimestrale e a ogni annuncio di fine supporto o modifica contrattuale del fornitore | S26: =IF($N26="","",IF($N26="Accettazione","CHIUSO",IF($N26="Trasferimento","APERTO","MONITORATO"))) -> MONITORATO
A27: 26 | B27: GOV-DOCUMENTATION-TRANSPARENCY -GDPR | C27: Governance e compliance | D27: Rischio di documentazione, trasparenza, tracciabilità o informazione agli utenti insufficienti riguardo a dati, prestazioni, limiti, versioni del modello e obblighi normativi applicabili a ISaAC, con possibile impossibilità di dimostrare la conformità, ricostruire le decisioni o utilizzo improprio del sistema da parte degli utenti. | E27: 3 | F27: 3 | G27: =E27*F27 -> 9 | H27: =IFERROR(IF(G27>=16,"Critico",IF(G27>=10,"Alto",IF(G27>=5,"Medio","Basso"))),"") -> Medio | I27: Sono mantenute la documentazione tecnica del sistema, delle versioni e delle prestazioni, oltre alla documentazione e alle istruzioni destinate a utenti e responsabili. | J27: =IFERROR(INDEX('Rischio residuo'!$I$2:$I$32,MATCH($A27,'Rischio residuo'!$A$2:$A$32,0)),"") -> 2 | K27: =IFERROR(INDEX('Rischio residuo'!$J$2:$J$32,MATCH($A27,'Rischio residuo'!$A$2:$A$32,0)),"") -> 3 | L27: =J27*K27 -> 6 | M27: =IFERROR(IF(L27>=16,"Critico",IF(L27>=10,"Alto",IF(L27>=5,"Medio","Basso"))),"") -> Medio | N27: =IF($M27="","",IF($M27="Basso","Accettazione",IF(IFERROR(INDEX('Rischio residuo'!$F$2:$F$32,MATCH($A27,'Rischio residuo'!$A$2:$A$32,0)),0)=0,"Trasferimento","Mitigazione"))) -> Mitigazione | O27: I. N. modifiche significative al sistema (modello, formato di inferenza, soglie, parametri) non riflesse nella documentazione tecnica e nel registro dei rischi entro 30 giorni > 0. II. N. versioni del modello in esercizio prive di scheda prestazioni e baseline di validazione documentate > 0. III. N. utilizzatori o responsabili che operano con istruzioni non aggiornate all'ultima versione rilasciata > 0. | P27: I. Collegare l'aggiornamento della documentazione tecnica e del registro dei rischi al processo di rilascio: nessun rilascio senza aggiornamento di versione, parametri di inferenza e prestazioni. II. Mantenere per ogni versione del modello una scheda di validazione con baseline delle metriche e parametri di inferenza applicati. III. Distribuire le istruzioni aggiornate a ogni rilascio e acquisire evidenza della presa in carico da parte di utilizzatori e responsabili. | Q27: Responsabile informatico | R27: Trimestrale | S27: =IF($N27="","",IF($N27="Accettazione","CHIUSO",IF($N27="Trasferimento","APERTO","MONITORATO"))) -> MONITORATO
A28: 27 | B28: GOV-ACCOUNTABILITY-AUDITABILITY -GDPR | C28: Governance e compliance | D28: Rischio di insufficiente definizione delle responsabilità, registrazione delle attività e conservazione delle evidenze relative al funzionamento e all'utilizzo di ISaAC, con possibile impossibilità di attribuire le operazioni eseguite, ricostruire eventi e decisioni, svolgere verifiche o dimostrare la conformità del sistema. | E28: 3 | F28: 4 | G28: =E28*F28 -> 12 | H28: =IFERROR(IF(G28>=16,"Critico",IF(G28>=10,"Alto",IF(G28>=5,"Medio","Basso"))),"") -> Alto | I28: Le attività rilevanti del sistema, le modifiche e gli eventi sono registrati e i ruoli e le responsabilità sono definiti. | J28: =IFERROR(INDEX('Rischio residuo'!$I$2:$I$32,MATCH($A28,'Rischio residuo'!$A$2:$A$32,0)),"") -> 2 | K28: =IFERROR(INDEX('Rischio residuo'!$J$2:$J$32,MATCH($A28,'Rischio residuo'!$A$2:$A$32,0)),"") -> 4 | L28: =J28*K28 -> 8 | M28: =IFERROR(IF(L28>=16,"Critico",IF(L28>=10,"Alto",IF(L28>=5,"Medio","Basso"))),"") -> Medio | N28: =IF($M28="","",IF($M28="Basso","Accettazione",IF(IFERROR(INDEX('Rischio residuo'!$F$2:$F$32,MATCH($A28,'Rischio residuo'!$A$2:$A$32,0)),0)=0,"Trasferimento","Mitigazione"))) -> Mitigazione | O28: I. N. eventi, accessi, modifiche o decisioni rilevanti non tracciabili tramite log o evidenza documentale > 0. | P28: I. Rafforzare logging e conservazione delle evidenze; definire le responsabilità e verificare periodicamente la completezza delle registrazioni. | Q28: Responsabile informatico | R28: Trimestrale e in caso di uso sospetto | S28: =IF($N28="","",IF($N28="Accettazione","CHIUSO",IF($N28="Trasferimento","APERTO","MONITORATO"))) -> MONITORATO
A29: 28 | B29: GOV-AI-CLASSIFICATION | C29: Governance e compliance | D29: Rischio di errata classificazione del sistema, mancato adeguamento normativo o cambiamento d'uso senza rivalutazione, con possibile applicazione di requisiti non corretti o mancato rispetto degli obblighi previsti. | E29: 2 | F29: 4 | G29: =E29*F29 -> 8 | H29: =IFERROR(IF(G29>=16,"Critico",IF(G29>=10,"Alto",IF(G29>=5,"Medio","Basso"))),"") -> Medio | I29: La classificazione del sistema è documentata ed è riesaminata in caso di modifiche significative. | J29: =IFERROR(INDEX('Rischio residuo'!$I$2:$I$32,MATCH($A29,'Rischio residuo'!$A$2:$A$32,0)),"") -> 1 | K29: =IFERROR(INDEX('Rischio residuo'!$J$2:$J$32,MATCH($A29,'Rischio residuo'!$A$2:$A$32,0)),"") -> 4 | L29: =J29*K29 -> 4 | M29: =IFERROR(IF(L29>=16,"Critico",IF(L29>=10,"Alto",IF(L29>=5,"Medio","Basso"))),"") -> Basso | N29: =IF($M29="","",IF($M29="Basso","Accettazione",IF(IFERROR(INDEX('Rischio residuo'!$F$2:$F$32,MATCH($A29,'Rischio residuo'!$A$2:$A$32,0)),0)=0,"Trasferimento","Mitigazione"))) -> Accettazione | Q29: Responsabile informatico | R29: Trimestrale e prima di ogni aggiornamento | S29: =IF($N29="","",IF($N29="Accettazione","CHIUSO",IF($N29="Trasferimento","APERTO","MONITORATO"))) -> CHIUSO
A30: 29 | B30: GOV-DEROGA-SCOPE | C30: Governance e compliance | D30: Rischio che l'utilizzo di ISaAC evolva verso un impiego che influenza decisioni riguardanti il singolo lavoratore facendo venir meno le condizioni della deroga di cui all'art. 6(3) del Regolamento (UE) 2024/1689 senza che ciò venga formalmente rilevato, valutato o gestito. | E30: 3 | F30: 5 | G30: =E30*F30 -> 15 | H30: =IFERROR(IF(G30>=16,"Critico",IF(G30>=10,"Alto",IF(G30>=5,"Medio","Basso"))),"") -> Alto | I30: La classificazione è riesaminata in caso di modifiche significative, ma senza un presidio dedicato al monitoraggio dello scopo d'uso. È in essere una clausola contrattuale che vieta l'impiego del sistema per valutazioni disciplinari, di performance o economiche. L'attestazione periodica del referente cliente sull'assenza di utilizzi per decisioni individuali e la verifica trimestrale dello scopo d'uso effettivo con evidenza documentale sono previste ma non ancora operative (Ruolo «Da implementare» in Controlli, peso 0: nessun effetto sull'LM — vedi LEGGENDA §5 e §9). | J30: =IFERROR(INDEX('Rischio residuo'!$I$2:$I$32,MATCH($A30,'Rischio residuo'!$A$2:$A$32,0)),"") -> 2 | K30: =IFERROR(INDEX('Rischio residuo'!$J$2:$J$32,MATCH($A30,'Rischio residuo'!$A$2:$A$32,0)),"") -> 5 | L30: =J30*K30 -> 10 | M30: =IFERROR(IF(L30>=16,"Critico",IF(L30>=10,"Alto",IF(L30>=5,"Medio","Basso"))),"") -> Alto | N30: =IF($M30="","",IF($M30="Basso","Accettazione",IF(IFERROR(INDEX('Rischio residuo'!$F$2:$F$32,MATCH($A30,'Rischio residuo'!$A$2:$A$32,0)),0)=0,"Trasferimento","Mitigazione"))) -> Mitigazione | O30: I. N. richieste o utilizzi documentati di ISaAC per finalità disciplinari, valutative o economiche verso singoli lavoratori > 0. II. Assenza di una verifica periodica formalizzata sullo scopo d'uso effettivo del sistema. | P30: I. Mantenere e presidiare la clausola contrattuale che vieta l'uso del sistema per decisioni individuali: verificarne la presenza a ogni rinnovo o modifica contrattuale e riesaminare formalmente ogni richiesta che vada in tal senso. II. Formalizzare l'attestazione periodica del referente cliente sull'assenza di utilizzo per decisioni individuali (presidio previsto, non ancora operativo). III. Istituire la verifica trimestrale dello scopo d'uso effettivo con evidenza documentale (presidio previsto, non ancora operativo). IV. Implementare il divieto tecnico di export o correlazione dei dati verso i sistemi di gestione del personale (owner: Responsabile informatico). A implementazione avvenuta dei punti II, III e IV, aggiornare il Ruolo dei controlli corrispondenti in "Controlli" da «Da implementare» al ruolo effettivo e verificare il nuovo rischio residuo. | Q30: Responsabile informatico | R30: Trimestrale | S30: =IF($N30="","",IF($N30="Accettazione","CHIUSO",IF($N30="Trasferimento","APERTO","MONITORATO"))) -> MONITORATO
A31: 30 | B31: GOV-DEROGA-DOC-MAINTENANCE | C31: Governance e compliance | D31: Rischio che la documentazione di valutazione a supporto della deroga art. 6 del Regolamento (UE) 2024/1689 non venga mantenuta aggiornata a seguito di modifiche al sistema, al caso d'uso o al contesto operativo, con conseguente esposizione in caso di ispezione da parte dell'autorità di vigilanza del mercato. | E31: 3 | F31: 4 | G31: =E31*F31 -> 12 | H31: =IFERROR(IF(G31>=16,"Critico",IF(G31>=10,"Alto",IF(G31>=5,"Medio","Basso"))),"") -> Alto | I31: Il riesame della classificazione è previsto ma non contempla esplicitamente l'aggiornamento della valutazione di deroga ex art. 6; nel processo di change management è inoltre previsto un passaggio obbligatorio che impone la revisione di tale valutazione entro trenta giorni da ogni modifica significativa. | J31: =IFERROR(INDEX('Rischio residuo'!$I$2:$I$32,MATCH($A31,'Rischio residuo'!$A$2:$A$32,0)),"") -> 2 | K31: =IFERROR(INDEX('Rischio residuo'!$J$2:$J$32,MATCH($A31,'Rischio residuo'!$A$2:$A$32,0)),"") -> 4 | L31: =J31*K31 -> 8 | M31: =IFERROR(IF(L31>=16,"Critico",IF(L31>=10,"Alto",IF(L31>=5,"Medio","Basso"))),"") -> Medio | N31: =IF($M31="","",IF($M31="Basso","Accettazione",IF(IFERROR(INDEX('Rischio residuo'!$F$2:$F$32,MATCH($A31,'Rischio residuo'!$A$2:$A$32,0)),0)=0,"Trasferimento","Mitigazione"))) -> Mitigazione | O31: I. N. modifiche significative al sistema, al caso d'uso o al contesto operativo non accompagnate da un aggiornamento della valutazione di deroga entro 30 giorni > 0. | P31: I. Mantenere il gate di deroga nel processo di change management: ogni modifica classificata come «significativa» include il passaggio obbligatorio di revisione della valutazione art. 6 entro 30 giorni, con evidenza documentale. II. Verificare a ogni revisione periodica che il gate sia stato effettivamente applicato a tutte le modifiche significative rilasciate nel periodo, e che il riesame della classificazione richiami esplicitamente l'aggiornamento della valutazione di deroga (oggi non lo prevede: è il punto debole residuo del presidio). | Q31: Responsabile informatico | R31: Trimestrale | S31: =IF($N31="","",IF($N31="Accettazione","CHIUSO",IF($N31="Trasferimento","APERTO","MONITORATO"))) -> MONITORATO
A32: 31 | B32: GOV-DEROGA-PROFILING-EXCLUSION -GDPR | C32: Governance e compliance | D32: Rischio che le rilevazioni di ISaAC vengano associate, anche indirettamente, a un'identità di lavoratore in modo persistente (es. tramite badge, matricola o correlazione ripetuta), qualificando l'attività come profiling ai sensi dell'art. 6(3) ultimo comma del Regolamento (UE) 2024/1689 e dell'art. 4(4) GDPR, con decadenza automatica della deroga indipendentemente dalla valutazione di rischio effettuata. | E32: 2 | F32: 5 | G32: =E32*F32 -> 10 | H32: =IFERROR(IF(G32>=16,"Critico",IF(G32>=10,"Alto",IF(G32>=5,"Medio","Basso"))),"") -> Alto | I32: Il sistema rileva DPI e postura, non l'identità delle persone: non impiega badge, matricole né riconoscimento facciale, escludendo qualsiasi identificazione persistente. | J32: =IFERROR(INDEX('Rischio residuo'!$I$2:$I$32,MATCH($A32,'Rischio residuo'!$A$2:$A$32,0)),"") -> 1 | K32: =IFERROR(INDEX('Rischio residuo'!$J$2:$J$32,MATCH($A32,'Rischio residuo'!$A$2:$A$32,0)),"") -> 5 | L32: =J32*K32 -> 5 | M32: =IFERROR(IF(L32>=16,"Critico",IF(L32>=10,"Alto",IF(L32>=5,"Medio","Basso"))),"") -> Medio | N32: =IF($M32="","",IF($M32="Basso","Accettazione",IF(IFERROR(INDEX('Rischio residuo'!$F$2:$F$32,MATCH($A32,'Rischio residuo'!$A$2:$A$32,0)),0)=0,"Trasferimento","Mitigazione"))) -> Mitigazione | O32: I. N. richieste, proposte tecniche o integrazioni che introducano identificazione persistente di individui > 0. | P32: I. Respingere o riprogettare richieste e integrazioni che introducano identificazione persistente (badge, matricola, riconoscimento facciale, correlazione ripetuta), documentando la valutazione di ogni richiesta. II. Rivedere annualmente la valutazione della deroga e aggiornarla ogni volta che cambia in modo sostanziale il sistema o il suo utilizzo. | Q32: Responsabile informatico | R32: Trimestrale | S32: =IF($N32="","",IF($N32="Accettazione","CHIUSO",IF($N32="Trasferimento","APERTO","MONITORATO"))) -> MONITORATO

Sheet Controlli
A1: # Rischio | B1: ID Rischio | C1: Controllo | D1: Descrizione controllo | E1: Copertura | F1: Affidabilità | G1: Efficacia | H1: Ruolo | I1: Peso | J1: LM (media pesata Efficacia)
A2: 1 | B2: =IFERROR(INDEX(Tabella!$B$2:$B$32,MATCH($A2,Tabella!$A$2:$A$32,0)),"") -> DEV-CHANGE-INTEGRITY_ISO | C2: Versionamento dev | D2: versionamento di codice, modelli, dataset, configurazioni | E2: 0.85 | F2: 0.95 | G2: =E2*F2 -> 0.8075 | H2: Primario | I2: =IF(TRIM(H2)="Primario", 3, IF(TRIM(H2)="Secondario", 2, IF(TRIM(H2)="Supporto", 1, 0))) -> 3 | J2: {=IFERROR(SUMPRODUCT(G:G,I:I,--($A:$A=$A2))/SUMIF($A:$A,$A2,I:I),0)} -> 0.69925
A3: 1 | B3: =IFERROR(INDEX(Tabella!$B$2:$B$32,MATCH($A3,Tabella!$A$2:$A$32,0)),"") -> DEV-CHANGE-INTEGRITY_ISO | C3: Rilascio controllato | D3: processo di rilascio con test, backup e rollback | E3: 0.85 | F3: 0.7 | G3: =E3*F3 -> 0.595 | H3: Primario | I3: =IF(TRIM(H3)="Primario", 3, IF(TRIM(H3)="Secondario", 2, IF(TRIM(H3)="Supporto", 1, 0))) -> 3 | J3: {=IFERROR(SUMPRODUCT(G:G,I:I,--($A:$A=$A3))/SUMIF($A:$A,$A3,I:I),0)} -> 0.69925
A4: 1 | B4: =IFERROR(INDEX(Tabella!$B$2:$B$32,MATCH($A4,Tabella!$A$2:$A$32,0)),"") -> DEV-CHANGE-INTEGRITY_ISO | C4: Hash modello | D4: hash del modello registrato per verificarne l'integrità | E4: 0.95 | F4: 0.95 | G4: =E4*F4 -> 0.9025 | H4: Secondario | I4: =IF(TRIM(H4)="Primario", 3, IF(TRIM(H4)="Secondario", 2, IF(TRIM(H4)="Supporto", 1, 0))) -> 2 | J4: {=IFERROR(SUMPRODUCT(G:G,I:I,--($A:$A=$A4))/SUMIF($A:$A,$A4,I:I),0)} -> 0.69925
